TESTS WITH ERRORS 
test10 (gradingtests.UnitTests)
Traceback (most recent call last):
  File "/Users/k2i/academics/automatedgradingapp/app/testing/kb-inference/gradingtests.py", line 279, in test10
    answer2 = KB.facts[KB.facts.index(fact3)].asserted
ValueError: Fact('fact', Statement('goodman', [Term(Constant('A'))]), True, [], [], []) is not in list

test14 (gradingtests.UnitTests)
Traceback (most recent call last):
  File "/Users/k2i/academics/automatedgradingapp/app/testing/kb-inference/gradingtests.py", line 405, in test14
    KB.kb_retract(fact2)
  File "/Users/k2i/academics/automatedgradingapp/app/testing/kb-inference/student_code.py", line 140, in kb_retract
    self.kb_retract_helper(i)
  File "/Users/k2i/academics/automatedgradingapp/app/testing/kb-inference/student_code.py", line 167, in kb_retract_helper
    self.facts.remove(factorrule)
ValueError: list.remove(x): x not in list

-------------------------------
TESTS FAILED  
test5 (gradingtests.UnitTests)
Traceback (most recent call last):
  File "/Users/k2i/academics/automatedgradingapp/app/testing/kb-inference/gradingtests.py", line 160, in test5
    self.assertTrue(len(answer7) > 0)
AssertionError: False is not true

-------------------------------
TESTS SKIPPED 
-------------------------------
